Workbook

Sheet overall_board
A1: overall_rank | B1: player_name | C1: team | D1: inferred_role | E1: adp | F1: adp_gap | G1: tier | H1: final_score | I1: dropoff_to_next | J1: note | K1: player_type | L1: taken
A2: 1 | B2: Shohei Ohtani | C2: LAD | D2: DH | E2: 1.26 | F2: 0.26 | G2: 1 | H2: 17.972 | I2: 0.861 | J2: speed specialist | K2: H
A3: 2 | B3: Aaron Judge | C3: NYY | D3: OF | E3: 1.86 | F3: -0.14 | G3: 2 | H3: 17.111 | I3: 1.186 | J3: power boost | K3: H
A4: 3 | B4: Juan Soto | C4: NYM | D4: OF | E4: 4.68 | F4: 1.68 | G4: 3 | H4: 15.925 | I4: 0.921 | J4: speed specialist | K4: H
A5: 4 | B5: Bobby Witt Jr. | C5: KCR | D5: SS | E5: 3.07 | F5: -0.93 | G5: 4 | H5: 15.005 | I5: 0.447 | J5: speed specialist | K5: H
A6: 5 | B6: Ronald Acuña Jr. | C6: ATL | D6: OF | E6: 5.32 | F6: 0.32 | G6: 4 | H6: 14.558 | I6: 1.543 | J6: speed specialist | K6: H
A7: 6 | B7: Tarik Skubal | C7: DET | D7: SP | E7: 6.91 | F7: 0.91 | G7: 5 | H7: 13.014 | I7: 0.254 | J7: strikeout arm | K7: P
A8: 7 | B8: José Ramírez | C8: CLE | D8: 3B | E8: 6.23 | F8: -0.77 | G8: 5 | H8: 12.761 | I8: 0.116 | J8: speed specialist | K8: H
A9: 8 | B9: Vladimir Guerrero Jr. | C9: TOR | D9: 1B | E9: 18.13 | F9: 10.13 | G9: 5 | H9: 12.645 | I9: 0.175 | J9: power boost | K9: H
A10: 9 | B10: Fernando Tatis Jr. | C10: SDP | D10: OF | E10: 14.06 | F10: 5.06 | G10: 5 | H10: 12.469 | I10: 0.524 | J10: speed specialist | K10: H
A11: 10 | B11: Kyle Tucker | C11: LAD | D11: OF | E11: 13.17 | F11: 3.17 | G11: 5 | H11: 11.945 | I11: 0.077 | J11: speed specialist | K11: H
A12: 11 | B12: Corbin Carroll | C12: ARI | D12: OF | E12: 14.14 | F12: 3.14 | G12: 5 | H12: 11.868 | I12: 0.151 | J12: speed specialist | K12: H
A13: 12 | B13: Julio Rodríguez | C13: SEA | D13: OF | E13: 9.54 | F13: -2.46 | G13: 5 | H13: 11.717 | I13: 0.081 | J13: speed specialist | K13: H
... A492: 491 | B492: Cody Bradford | C492: TEX | D492: P | E492: 999 | F492: 508 | G492: 21 | H492: 2.098 | I492: 0.007 | J492: pitching depth | K492: P
A493: 492 | B493: Luis Garcia | D493: RP | E493: 999 | F493: 507 | G493: 21 | H493: 2.091 | I493: 0.007 | J493: pitching depth | K493: P
A494: 493 | B494: Christopher Morel | C494: MIA | D494: OF | E494: 999 | F494: 506 | G494: 21 | H494: 2.085 | I494: 0.005 | J494: value target | K494: H
A495: 494 | B495: Ryan Jeffers | C495: MIN | D495: C | E495: 296.52 | F495: -197.48 | G495: 21 | H495: 2.08 | I495: 0.006 | J495: value target | K495: H
A496: 495 | B496: Matt Gage | C496: SFG | D496: RP | E496: 999 | F496: 504 | G496: 21 | H496: 2.074 | I496: 0.013 | J496: pitching depth | K496: P
A497: 496 | B497: Jordan Hicks | C497: CHW | D497: RP | E497: 999 | F497: 503 | G497: 21 | H497: 2.061 | I497: 0.012 | J497: pitching depth | K497: P
A498: 497 | B498: Grant Anderson | C498: MIL | D498: RP | E498: 999 | F498: 502 | G498: 21 | H498: 2.049 | I498: 0.005 | J498: pitching depth | K498: P
A499: 498 | B499: Cole Sulser | C499: TBR | D499: RP | E499: 999 | F499: 501 | G499: 22 | H499: 2.044 | I499: 0.004 | J499: pitching depth | K499: P
A500: 499 | B500: Anthony Kay | C500: CHW | D500: SP | E500: 717.81 | F500: 218.81 | G500: 22 | H500: 2.04 | I500: 0.011 | J500: SP value | K500: P
A501: 500 | B501: Josh Sborz | C501: TEX | D501: RP | E501: 999 | F501: 499 | G501: 22 | H501: 2.029 | I501: 0.004 | J501: pitching depth | K501: P
A502: 501 | B502: Jalen Beeks | C502: TEX | D502: RP | E502: 999 | F502: 498 | G502: 22 | H502: 2.024 | I502: 0.001 | J502: pitching depth | K502: P
A503: 502 | B503: Nasim Nuñez | C503: WSN | D503: SS | E503: 597.17 | F503: 95.17 | G503: 22 | H503: 2.023 | I503: 0.008 | J503: speed specialist | K503: H
A504: 503 | B504: Cade Horton | C504: CHC | D504: SP | E504: 179.83 | F504: -323.17 | G504: 22 | H504: 2.015 | I504: 0.001 | J504: pitching depth | K504: P
A505: 504 | B505: Ryne Stanek | C505: STL | D505: RP | E505: 748.14 | F505: 244.14 | G505: 22 | H505: 2.014 | I505: 0.005 | J505: RP saves+holds | K505: P
... A568: 567 | B568: Jac Caglianone | C568: KCR | D568: OF | E568: 167.34 | F568: -399.66 | G568: 24 | H568: 1.424 | I568: 0.002 | J568: balanced bat | K568: H
A569: 568 | E569: 999 | F569: 431 | G569: 24 | H569: 1.421 | I569: 0.004 | J569: pitching depth | K569: P
A570: 569 | B570: Spencer Steer | C570: CIN | D570: 1B | E570: 335.43 | F570: -233.57 | G570: 24 | H570: 1.417 | I570: 0.001 | J570: value target | K570: H
A571: 570 | B571: Will Klein | C571: LAD | D571: RP | E571: 999 | F571: 429 | G571: 24 | H571: 1.416 | I571: 0.013 | J571: pitching depth | K571: P
A572: 571 | B572: Austin Hays | C572: CHW | D572: OF | E572: 587.93 | F572: 16.93 | G572: 24 | H572: 1.404 | I572: 0.006 | J572: value target | K572: H
A573: 572 | B573: Hunter Bigge | C573: TBR | D573: RP | E573: 999 | F573: 427 | G573: 24 | H573: 1.398 | I573: 0.006 | J573: pitching depth | K573: P
A574: 573 | B574: Sam Hentges | C574: SFG | D574: RP | E574: 999 | F574: 426 | G574: 24 | H574: 1.392 | I574: 0.005 | J574: pitching depth | K574: P
A575: 574 | B575: DL Hall | C575: MIL | D575: RP | E575: 999 | F575: 425 | G575: 24 | H575: 1.387 | I575: 0.009 | J575: pitching depth | K575: P
A576: 575 | B576: Matt Vierling | C576: DET | D576: OF | E576: 999 | F576: 424 | G576: 24 | H576: 1.377 | I576: 0.03 | J576: value target | K576: H
A577: 576 | B577: Moisés Ballesteros | C577: CHC | D577: C | E577: 611.1 | F577: 35.1 | G577: 24 | H577: 1.348 | I577: 0.014 | J577: ratio stabilizer | K577: H
A578: 577 | B578: Kyle Harrison | C578: MIL | D578: SP | E578: 475.18 | F578: -101.82 | G578: 24 | H578: 1.334 | I578: 0.002 | J578: SP value | K578: P
A579: 578 | B579: Kevin Kelly | C579: TBR | D579: RP | E579: 999 | F579: 421 | G579: 24 | H579: 1.332 | I579: 0.005 | J579: pitching depth | K579: P
A580: 579 | B580: Hayden Harris | C580: ATL | D580: RP | E580: 999 | F580: 420 | G580: 24 | H580: 1.327 | I580: 0.001 | J580: pitching depth | K580: P
...

Sheet hitters_board
A1: final_rank | B1: player_name | C1: team | D1: inferred_role | E1: position | F1: PA | G1: R | H1: RBI | I1: HR | J1: SB | K1: AVG | L1: OBP | M1: adp | N1: adp_gap | O1: tier | P1: final_score | Q1: dropoff_to_next | R1: note
A2: 1 | B2: Shohei Ohtani | C2: LAD | D2: DH | E2: DH | F2: 659.45 | G2: 120.75 | H2: 107.978 | I2: 45.536 | J2: 23.74 | K2: 0.281 | L2: 0.384 | M2: 1.26 | N2: 0.26 | O2: 1 | P2: 17.972 | Q2: 0.861 | R2: speed specialist
A3: 2 | B3: Aaron Judge | C3: NYY | D3: OF | E3: OF | F3: 636.129 | G3: 107.577 | H3: 110.556 | I3: 45.797 | J3: 8.561 | K3: 0.287 | L3: 0.417 | M3: 1.86 | N3: -0.14 | O3: 2 | P3: 17.111 | Q3: 1.186 | R3: power boost
A4: 3 | B4: Juan Soto | C4: NYM | D4: OF | E4: OF | F4: 658.29 | G4: 107.336 | H4: 95.688 | I4: 36.957 | J4: 19.645 | K4: 0.272 | L4: 0.409 | M4: 4.68 | N4: 1.68 | O4: 3 | P4: 15.925 | Q4: 0.921 | R4: speed specialist
A5: 4 | B5: Bobby Witt Jr. | C5: KCR | D5: SS | E5: SS | F5: 650.443 | G5: 100.778 | H5: 91.936 | I5: 28.99 | J5: 33.745 | K5: 0.292 | L5: 0.349 | M5: 3.07 | N5: -0.93 | O5: 4 | P5: 15.005 | Q5: 0.447 | R5: speed specialist
A6: 5 | B6: Ronald Acuña Jr. | C6: ATL | D6: OF | E6: OF | F6: 645.549 | G6: 105.845 | H6: 80.97 | I6: 29.449 | J6: 24.956 | K6: 0.281 | L6: 0.385 | M6: 5.32 | N6: 0.32 | O6: 4 | P6: 14.558 | Q6: 1.797 | R6: speed specialist
A7: 6 | B7: José Ramírez | C7: CLE | D7: 3B | E7: 3B | F7: 633.09 | G7: 88.733 | H7: 87.207 | I7: 27.1 | J7: 32.247 | K7: 0.273 | L7: 0.347 | M7: 6.23 | N7: 0.23 | O7: 5 | P7: 12.761 | Q7: 0.116 | R7: speed specialist
A8: 7 | B8: Vladimir Guerrero Jr. | C8: TOR | D8: 1B | E8: 1B | F8: 653.597 | G8: 94.725 | H8: 97.29 | I8: 30.65 | J8: 5.047 | K8: 0.296 | L8: 0.381 | M8: 18.13 | N8: 11.13 | O8: 5 | P8: 12.645 | Q8: 0.175 | R8: power boost
A9: 8 | B9: Fernando Tatis Jr. | C9: SDP | D9: OF | E9: OF | F9: 638.128 | G9: 98.122 | H9: 82.178 | I9: 29.326 | J9: 24.218 | K9: 0.272 | L9: 0.357 | M9: 14.06 | N9: 6.06 | O9: 5 | P9: 12.469 | Q9: 0.524 | R9: speed specialist
A10: 9 | B10: Kyle Tucker | C10: LAD | D10: OF | E10: OF | F10: 599.986 | G10: 93.196 | H10: 84.12 | I10: 28.388 | J10: 19.815 | K10: 0.269 | L10: 0.37 | M10: 13.17 | N10: 4.17 | O10: 5 | P10: 11.945 | Q10: 0.077 | R10: speed specialist
A11: 10 | B11: Corbin Carroll | C11: ARI | D11: OF | E11: OF | F11: 607.431 | G11: 96.51 | H11: 78.267 | I11: 25.974 | J11: 32.598 | K11: 0.259 | L11: 0.346 | M11: 14.14 | N11: 4.14 | O11: 5 | P11: 11.868 | Q11: 0.151 | R11: speed specialist
A12: 11 | B12: Julio Rodríguez | C12: SEA | D12: OF | E12: OF | F12: 645.328 | G12: 91.561 | H12: 90.343 | I12: 29.432 | J12: 25.592 | K12: 0.273 | L12: 0.334 | M12: 9.54 | N12: -1.46 | O12: 5 | P12: 11.717 | Q12: 0.12 | R12: speed specialist
A13: 12 | B13: Yordan Alvarez | C13: HOU | D13: OF | E13: OF | F13: 553.289 | G13: 81.297 | H13: 88.405 | I13: 30.495 | J13: 3.632 | K13: 0.294 | L13: 0.39 | M13: 33.21 | N13: 21.21 | O13: 5 | P13: 11.596 | Q13: 0.058 | R13: power boost
... A113: 112 | B113: Sal Stewart | C113: CIN | D113: 1B | E113: 1B | F113: 460.165 | G113: 57.062 | H113: 61.531 | I113: 17.354 | J113: 6.266 | K113: 0.268 | L113: 0.33 | M113: 166.11 | N113: 54.11 | O113: 9 | P113: 4.365 | Q113: 0.027 | R113: ratio stabilizer
A114: 113 | B114: Luis García Jr. | C114: WSN | D114: BAT | F114: 478.097 | G114: 54.416 | H114: 58.745 | I114: 14.402 | J114: 12.95 | K114: 0.268 | L114: 0.309 | M114: 259.77 | N114: 146.77 | O114: 9 | P114: 4.338 | Q114: 0.01 | R114: ratio stabilizer
A115: 114 | B115: Nolan Arenado | C115: ARI | D115: 3B | E115: 3B | F115: 549.168 | G115: 60.007 | H115: 69.25 | I115: 16.285 | J115: 2.733 | K115: 0.254 | L115: 0.308 | M115: 641.79 | N115: 527.79 | O115: 9 | P115: 4.327 | Q115: 0.015 | R115: value target
A116: 115 | B116: Tyler Freeman | C116: COL | D116: OF | E116: OF | F116: 296.607 | G116: 37.825 | H116: 27.941 | I116: 4.884 | J116: 11.695 | K116: 0.279 | L116: 0.352 | M116: 745.42 | N116: 630.42 | O116: 9 | P116: 4.312 | Q116: 0.03 | R116: ratio stabilizer
A117: 116 | B117: Spencer Horwitz | C117: PIT | D117: 1B | E117: 1B | F117: 449.336 | G117: 51.902 | H117: 48.853 | I117: 10.419 | J117: 1.817 | K117: 0.258 | L117: 0.346 | M117: 739.93 | N117: 623.93 | O117: 9 | P117: 4.282 | Q117: 0.029 | R117: ratio stabilizer
A118: 117 | B118: Colt Keith | C118: DET | D118: 3B | E118: 3B | F118: 491.766 | G118: 60.094 | H118: 56.203 | I118: 14.995 | J118: 3.518 | K118: 0.258 | L118: 0.328 | M118: 494.52 | N118: 377.52 | O118: 9 | P118: 4.253 | Q118: 0.025 | R118: ratio stabilizer
A119: 118 | B119: Marcus Semien | C119: NYM | D119: 2B | E119: 2B | F119: 592.41 | G119: 71.785 | H119: 67.972 | I119: 19.035 | J119: 8.96 | K119: 0.242 | L119: 0.313 | M119: 265.13 | N119: 147.13 | O119: 9 | P119: 4.229 | Q119: 0.026 | R119: value target
A120: 119 | B120: Ceddanne Rafaela | C120: BOS | D120: OF | E120: OF | F120: 539.447 | G120: 64.948 | H120: 62.323 | I120: 16.006 | J120: 19.216 | K120: 0.253 | L120: 0.294 | M120: 126.17 | N120: 7.17 | O120: 9 | P120: 4.203 | Q120: 0.012 | R120: speed specialist
A121: 120 | B121: Wilyer Abreu | C121: BOS | D121: OF | E121: OF | F121: 478.347 | G121: 60.37 | H121: 65.596 | I121: 20.615 | J121: 7.824 | K121: 0.245 | L121: 0.326 | M121: 201.88 | N121: 81.88 | O121: 9 | P121: 4.191 | Q121: 0.054 | R121: power boost
A122: 121 | B122: Jordan Westburg | C122: BAL | D122: 3B | E122: 3B | F122: 401.205 | G122: 53.268 | H122: 51.746 | I122: 16.188 | J122: 4.207 | K122: 0.262 | L122: 0.317 | M122: 631.38 | N122: 510.38 | O122: 9 | P122: 4.137 | Q122: 0.005 | R122: ratio stabilizer
A123: 122 | B123: Jung Hoo Lee | C123: SFG | D123: OF | E123: OF | F123: 532.605 | G123: 60.719 | H123: 52.877 | I123: 7.899 | J123: 8.525 | K123: 0.269 | L123: 0.329 | M123: 339.77 | N123: 217.77 | O123: 9 | P123: 4.132 | Q123: 0.017 | R123: ratio stabilizer
A124: 123 | B124: Jonathan India | C124: KCR | D124: 2B | E124: 2B | F124: 493.064 | G124: 58.817 | H124: 49.048 | I124: 11.606 | J124: 6.15 | K124: 0.246 | L124: 0.339 | M124: 612.3 | N124: 489.3 | O124: 9 | P124: 4.114 | Q124: 0.018 | R124: ratio stabilizer
A125: 124 | B125: Sal Frelick | C125: MIL | D125: OF | E125: OF | F125: 515.378 | G125: 59.189 | H125: 49.168 | I125: 7.473 | J125: 16.269 | K125: 0.262 | L125: 0.328 | M125: 215.19 | N125: 91.19 | O125: 9 | P125: 4.096 | Q125: 0.108 | R125: speed specialist
A126: 125 | B126: J.P. Crawford | C126: SEA | D126: SS | E126: SS | F126: 549.913 | G126: 61.352 | H126: 49.776 | I126: 10.321 | J126: 4.833 | K126: 0.241 | L126: 0.334 | M126: 748.33 | N126: 623.33 | O126: 9 | P126: 3.988 | Q126: 0.007 | R126: ratio stabilizer
... A198: 197 | B198: Noelvi Marte | C198: CIN | D198: OF | E198: OF | F198: 454.672 | G198: 54.209 | H198: 53.611 | I198: 14.81 | J198: 12.694 | K198: 0.251 | L198: 0.303 | M198: 147.03 | N198: -49.97 | O198: 12 | P198: 2.421 | Q198: 0.046 | R198: balanced bat
A199: 198 | B199: Victor Scott II | C199: STL | D199: BAT | F199: 476.33 | G199: 53.04 | H199: 36.566 | I199: 7.058 | J199: 30.093 | K199: 0.223 | L199: 0.293 | M199: 382.93 | N199: 184.93 | O199: 12 | P199: 2.375 | Q199: 0.012 | R199: speed specialist
A200: 199 | B200: Mike Yastrzemski | C200: ATL | D200: OF | E200: OF | F200: 433.143 | G200: 52.208 | H200: 49.474 | I200: 15.298 | J200: 4.286 | K200: 0.229 | L200: 0.318 | M200: 647.71 | N200: 448.71 | O200: 12 | P200: 2.363 | Q200: 0.01 | R200: value target
A201: 200 | B201: Tommy Edman | C201: LAD | D201: 2B | E201: 2B | F201: 394.94 | G201: 48.06 | H201: 44.096 | I201: 10.757 | J201: 7.786 | K201: 0.246 | L201: 0.301 | M201: 728.27 | N201: 528.27 | O201: 12 | P201: 2.353 | Q201: 0.043 | R201: value target
A202: 201 | B202: Cedric Mullins | C202: TBR | D202: BAT | F202: 435.819 | G202: 51.682 | H202: 47.715 | I202: 13.984 | J202: 18.456 | K202: 0.227 | L202: 0.302 | M202: 325.35 | N202: 124.35 | O202: 12 | P202: 2.31 | Q202: 0.07 | R202: speed specialist
A203: 202 | B203: Jordan Walker | C203: STL | D203: OF | E203: OF | F203: 477.602 | G203: 51.336 | H203: 53.275 | I203: 14.602 | J203: 8.523 | K203: 0.239 | L203: 0.301 | M203: 493.5 | N203: 291.5 | O203: 12 | P203: 2.24 | Q203: 0.062 | R203: value target
A204: 203 | B204: Tyler O'Neill | C204: BAL | D204: OF | E204: OF | F204: 381.948 | G204: 48.452 | H204: 50.331 | I204: 18.018 | J204: 4.341 | K204: 0.233 | L204: 0.318 | M204: 496.11 | N204: 293.11 | O204: 12 | P204: 2.178 | Q204: 0.03 | R204: value target
A205: 204 | B205: Nathan Lukes | C205: TOR | D205: OF | E205: OF | F205: 293.456 | G205: 33.637 | H205: 30.091 | I205: 5.608 | J205: 2.811 | K205: 0.262 | L205: 0.324 | M205: 999 | N205: 795 | O205: 12 | P205: 2.148 | Q205: 0.063 | R205: ratio stabilizer
A206: 205 | B206: Christopher Morel | C206: MIA | D206: OF | E206: OF | F206: 337.889 | G206: 39.328 | H206: 41.493 | I206: 13.464 | J206: 6.461 | K206: 0.223 | L206: 0.302 | M206: 999 | N206: 794 | O206: 12 | P206: 2.085 | Q206: 0.005 | R206: value target
A207: 206 | B207: Ryan Jeffers | C207: MIN | D207: C | E207: C | F207: 487.378 | G207: 55.591 | H207: 55.306 | I207: 15.606 | J207: 2.441 | K207: 0.242 | L207: 0.325 | M207: 296.52 | N207: 90.52 | O207: 12 | P207: 2.08 | Q207: 0.057 | R207: value target
A208: 207 | B208: Nasim Nuñez | C208: WSN | D208: SS | E208: SS | F208: 352.717 | G208: 39.763 | H208: 26.778 | I208: 4.825 | J208: 24.517 | K208: 0.23 | L208: 0.304 | M208: 597.17 | N208: 390.17 | O208: 12 | P208: 2.023 | Q208: 0.014 | R208: speed specialist
A209: 208 | B209: Gavin Lux | C209: TBR | D209: 2B | E209: 2B | F209: 406.852 | G209: 44.234 | H209: 39.168 | I209: 6.109 | J209: 2.846 | K209: 0.252 | L209: 0.329 | M209: 745.56 | N209: 537.56 | O209: 12 | P209: 2.009 | Q209: 0.014 | R209: value target
A210: 209 | B210: Dylan Crews | C210: WSN | D210: OF | E210: OF | F210: 411.925 | G210: 48.371 | H210: 44.377 | I210: 12.197 | J210: 17.717 | K210: 0.238 | L210: 0.301 | M210: 257.3 | N210: 48.3 | O210: 12 | P210: 1.995 | Q210: 0 | R210: speed specialist
...

Sheet pitchers_board
A1: final_rank | B1: player_name | C1: team | D1: inferred_role | E1: IP | F1: QS | G1: K | H1: ERA | I1: WHIP | J1: Saves_plus_Holds | K1: adp | L1: adp_gap | M1: tier | N1: final_score | O1: dropoff_to_next | P1: note
A2: 1 | B2: Tarik Skubal | C2: DET | D2: SP | E2: 195.161 | F2: 20.66 | G2: 237.37 | H2: 2.732 | I2: 0.991 | J2: 0 | K2: 6.91 | L2: 5.91 | M2: 1 | N2: 13.014 | O2: 1.379 | P2: strikeout arm
A3: 2 | B3: Paul Skenes | C3: PIT | D3: SP | E3: 189.148 | F3: 19.699 | G3: 227.237 | H3: 2.833 | I3: 1.059 | J3: 0 | K3: 9.66 | L3: 7.66 | M3: 2 | N3: 11.635 | O3: 0.468 | P3: strikeout arm
A4: 3 | B4: Garrett Crochet | C4: BOS | D4: SP | E4: 189.961 | F4: 19.217 | G4: 234.562 | H4: 3.001 | I4: 1.074 | J4: 0 | K4: 12.1 | L4: 9.1 | M4: 3 | N4: 11.167 | O4: 2.072 | P4: strikeout arm
A5: 4 | B5: Chris Sale | C5: ATL | D5: SP | E5: 163.023 | F5: 16.288 | G5: 199.097 | H5: 3.175 | I5: 1.093 | J5: 0 | K5: 39.21 | L5: 35.21 | M5: 4 | N5: 9.096 | O5: 0.268 | P5: strikeout arm
A6: 5 | B6: Bryan Woo | C6: SEA | D6: SP | E6: 190.426 | F6: 17.579 | G6: 191.768 | H6: 3.488 | I6: 1.08 | J6: 0 | K6: 34.9 | L6: 29.9 | M6: 4 | N6: 8.828 | O6: 0.046 | P6: strikeout arm
A7: 6 | B7: Cristopher Sánchez | C7: PHI | D7: SP | E7: 194.47 | F7: 19.035 | G7: 188.252 | H7: 3.18 | I7: 1.161 | J7: 0 | K7: 25.17 | L7: 19.17 | M7: 4 | N7: 8.782 | O7: 0.376 | P7: strikeout arm
A8: 7 | B8: Logan Webb | C8: SFG | D8: SP | E8: 198.436 | F8: 19.099 | G8: 188.076 | H8: 3.271 | I8: 1.19 | J8: 0.071 | K8: 57.73 | L8: 50.73 | M8: 4 | N8: 8.406 | O8: 0.149 | P8: strikeout arm
A9: 8 | B9: Logan Gilbert | C9: SEA | D9: SP | E9: 166.138 | F9: 15.346 | G9: 183.206 | H9: 3.413 | I9: 1.075 | J9: 0 | K9: 37.11 | L9: 29.11 | M9: 4 | N9: 8.257 | O9: 0.045 | P9: strikeout arm
A10: 9 | B10: Jacob deGrom | C10: TEX | D10: SP | E10: 166.575 | F10: 15.1 | G10: 189.055 | H10: 3.483 | I10: 1.078 | J10: 0 | K10: 49.97 | L10: 40.97 | M10: 4 | N10: 8.212 | O10: 0.174 | P10: strikeout arm
A11: 10 | B11: Mason Miller | C11: SDP | D11: RP | E11: 65.349 | F11: 0.021 | G11: 102.588 | H11: 2.436 | I11: 0.986 | J11: 34.456 | K11: 28.08 | L11: 18.08 | M11: 4 | N11: 8.038 | O11: 0.191 | P11: RP saves+holds
A12: 11 | B12: Zack Wheeler | C12: PHI | D12: SP | E12: 145.378 | F12: 14.533 | G12: 164.917 | H12: 3.266 | I12: 1.092 | J12: 0 | K12: 111.97 | L12: 100.97 | M12: 4 | N12: 7.847 | O12: 0.018 | P12: strikeout arm
A13: 12 | B13: Cole Ragans | C13: KCR | D13: SP | E13: 163.259 | F13: 15.557 | G13: 201.553 | H13: 3.382 | I13: 1.165 | J13: 0 | K13: 47.78 | L13: 35.78 | M13: 4 | N13: 7.829 | O13: 0.053 | P13: strikeout arm
... A288: 287 | B288: Cody Bradford | C288: TEX | D288: P | E288: 65.529 | F288: 2.723 | G288: 57.568 | H288: 4.259 | I288: 1.214 | J288: 0.851 | K288: 999 | L288: 712 | M288: 13 | N288: 2.098 | O288: 0.007 | P288: pitching depth
A289: 288 | B289: Luis Garcia | D289: RP | E289: 47.566 | F289: 0.225 | G289: 44.106 | H289: 4.099 | I289: 1.296 | J289: 9.429 | K289: 999 | L289: 711 | M289: 13 | N289: 2.091 | O289: 0.017 | P289: pitching depth
A290: 289 | B290: Matt Gage | C290: SFG | D290: RP | E290: 54.335 | F290: 0 | G290: 46.871 | H290: 3.882 | I290: 1.328 | J290: 8.49 | K290: 999 | L290: 710 | M290: 13 | N290: 2.074 | O290: 0.013 | P290: pitching depth
A291: 290 | B291: Jordan Hicks | C291: CHW | D291: RP | E291: 60.654 | F291: 0.12 | G291: 56.453 | H291: 4.11 | I291: 1.379 | J291: 11.497 | K291: 999 | L291: 709 | M291: 13 | N291: 2.061 | O291: 0.012 | P291: pitching depth
A292: 291 | B292: Grant Anderson | C292: MIL | D292: RP | E292: 56.044 | F292: 0 | G292: 55.572 | H292: 4.181 | I292: 1.315 | J292: 9.138 | K292: 999 | L292: 708 | M292: 13 | N292: 2.049 | O292: 0.005 | P292: pitching depth
A293: 292 | B293: Cole Sulser | C293: TBR | D293: RP | E293: 54.657 | F293: 0 | G293: 49.312 | H293: 4.094 | I293: 1.302 | J293: 8.75 | K293: 999 | L293: 707 | M293: 13 | N293: 2.044 | O293: 0.004 | P293: pitching depth
A294: 293 | B294: Anthony Kay | C294: CHW | D294: SP | E294: 134.589 | F294: 9.07 | G294: 109.505 | H294: 4.318 | I294: 1.393 | J294: 0.574 | K294: 717.81 | L294: 424.81 | M294: 13 | N294: 2.04 | O294: 0.011 | P294: SP value
A295: 294 | B295: Josh Sborz | C295: TEX | D295: RP | E295: 51.611 | F295: 0 | G295: 52.659 | H295: 4.088 | I295: 1.313 | J295: 8.554 | K295: 999 | L295: 705 | M295: 13 | N295: 2.029 | O295: 0.004 | P295: pitching depth
A296: 295 | B296: Jalen Beeks | C296: TEX | D296: RP | E296: 53.775 | F296: 0 | G296: 48.676 | H296: 3.953 | I296: 1.33 | J296: 8.736 | K296: 999 | L296: 704 | M296: 13 | N296: 2.024 | O296: 0.009 | P296: pitching depth
A297: 296 | B297: Cade Horton | C297: CHC | D297: SP | E297: 129.815 | F297: 9.677 | G297: 113.029 | H297: 4.112 | I297: 1.268 | J297: 0 | K297: 179.83 | L297: -116.17 | M297: 13 | N297: 2.015 | O297: 0.001 | P297: pitching depth
A298: 297 | B298: Ryne Stanek | C298: STL | D298: RP | E298: 58.414 | F298: 0 | G298: 59.753 | H298: 4.118 | I298: 1.355 | J298: 15.904 | K298: 748.14 | L298: 451.14 | M298: 13 | N298: 2.014 | O298: 0.018 | P298: RP saves+holds
A299: 298 | B299: Ryan Zeferjahn | C299: LAA | D299: RP | E299: 59.491 | F299: 0 | G299: 64.774 | H299: 4.386 | I299: 1.392 | J299: 13.42 | K299: 999 | L299: 701 | M299: 13 | N299: 1.996 | O299: 0.005 | P299: pitching depth
A300: 299 | B300: Tyler Wells | C300: BAL | D300: P | E300: 70.34 | F300: 2.001 | G300: 64.376 | H300: 4.302 | I300: 1.204 | J300: 6.302 | K300: 748.25 | L300: 449.25 | M300: 13 | N300: 1.991 | O300: 0.001 | P300: pitching depth
A301: 300 | B301: Jacob Webb | C301: CHC | D301: RP | E301: 53.679 | F301: 0 | G301: 50.22 | H301: 4.259 | I301: 1.304 | J301: 10.068 | K301: 999 | L301: 699 | M301: 13 | N301: 1.99 | O301: 0.012 | P301: pitching depth
... A343: 342 | B343: Connor Phillips | C343: CIN | D343: RP | E343: 56.318 | F343: 0 | G343: 60.29 | H343: 4.42 | I343: 1.368 | J343: 9.877 | K343: 999 | L343: 657 | M343: 15 | N343: 1.426 | O343: 0.004 | P343: pitching depth
A344: 343 | E344: 28 | F344: 0 | G344: 30.645 | H344: 3.516 | I344: 1.181 | J344: 0.87 | K344: 999 | L344: 656 | M344: 15 | N344: 1.421 | O344: 0.005 | P344: pitching depth
A345: 344 | B345: Will Klein | C345: LAD | D345: RP | E345: 54.912 | F345: 0 | G345: 59.336 | H345: 4.264 | I345: 1.453 | J345: 12.579 | K345: 999 | L345: 655 | M345: 15 | N345: 1.416 | O345: 0.019 | P345: pitching depth
A346: 345 | B346: Hunter Bigge | C346: TBR | D346: RP | E346: 50.215 | F346: 0 | G346: 50.843 | H346: 4.171 | I346: 1.333 | J346: 6.973 | K346: 999 | L346: 654 | M346: 15 | N346: 1.398 | O346: 0.006 | P346: pitching depth
A347: 346 | B347: Sam Hentges | C347: SFG | D347: RP | E347: 28.973 | F347: 0 | G347: 29.424 | H347: 3.406 | I347: 1.237 | J347: 2.033 | K347: 999 | L347: 653 | M347: 15 | N347: 1.392 | O347: 0.005 | P347: pitching depth
A348: 347 | B348: DL Hall | C348: MIL | D348: RP | E348: 53.114 | F348: 0.004 | G348: 51.849 | H348: 3.989 | I348: 1.338 | J348: 5.891 | K348: 999 | L348: 652 | M348: 15 | N348: 1.387 | O348: 0.053 | P348: pitching depth
A349: 348 | B349: Kyle Harrison | C349: MIL | D349: SP | E349: 103.804 | F349: 6.207 | G349: 104.129 | H349: 4.27 | I349: 1.321 | J349: 1.026 | K349: 475.18 | L349: 127.18 | M349: 15 | N349: 1.334 | O349: 0.002 | P349: SP value
A350: 349 | B350: Kevin Kelly | C350: TBR | D350: RP | E350: 41.341 | F350: 0 | G350: 36.233 | H350: 3.879 | I350: 1.211 | J350: 1.909 | K350: 999 | L350: 650 | M350: 15 | N350: 1.332 | O350: 0.005 | P350: pitching depth
A351: 350 | B351: Hayden Harris | C351: ATL | D351: RP | E351: 45.518 | F351: 0 | G351: 48.311 | H351: 3.961 | I351: 1.317 | J351: 4.967 | K351: 999 | L351: 649 | M351: 15 | N351: 1.327 | O351: 0.011 | P351: pitching depth
A352: 351 | B352: Victor Vodnik | C352: COL | D352: RP | E352: 63.342 | F352: 0 | G352: 61.555 | H352: 4.348 | I352: 1.472 | J352: 25.941 | K352: 516.66 | L352: 165.66 | M352: 15 | N352: 1.316 | O352: 0.017 | P352: RP saves+holds
A353: 352 | B353: Kyle Leahy | C353: STL | D353: SP | E353: 118.406 | F353: 5.776 | G353: 96.093 | H353: 4.325 | I353: 1.374 | J353: 1.233 | K353: 734.79 | L353: 382.79 | M353: 15 | N353: 1.299 | O353: 0.044 | P353: SP value
A354: 353 | B354: Michael Kelly | C354: ATH | D354: RP | E354: 58.273 | F354: 0 | G354: 50.907 | H354: 4.488 | I354: 1.41 | J354: 13.463 | K354: 999 | L354: 646 | M354: 15 | N354: 1.255 | O354: 0.012 | P354: pitching depth
A355: 354 | B355: Javier Assad | C355: CHC | D355: P | E355: 63.432 | F355: 1.174 | G355: 53.503 | H355: 4.108 | I355: 1.332 | J355: 3.852 | K355: 999 | L355: 645 | M355: 15 | N355: 1.243 | O355: 0.006 | P355: pitching depth
...

Sheet tier_sheet
A1: board_type | B1: overall_rank | C1: player_name | D1: inferred_role | E1: tier | F1: final_score | G1: dropoff_to_next
A2: overall | B2: 1 | C2: Shohei Ohtani | D2: DH | E2: 1 | F2: 17.972 | G2: 0.861
A3: overall | B3: 2 | C3: Aaron Judge | D3: OF | E3: 2 | F3: 17.111 | G3: 1.186
A4: overall | B4: 3 | C4: Juan Soto | D4: OF | E4: 3 | F4: 15.925 | G4: 0.921
A5: overall | B5: 4 | C5: Bobby Witt Jr. | D5: SS | E5: 4 | F5: 15.005 | G5: 0.447
A6: overall | B6: 5 | C6: Ronald Acuña Jr. | D6: OF | E6: 4 | F6: 14.558 | G6: 1.543
A7: overall | B7: 6 | C7: Tarik Skubal | D7: SP | E7: 5 | F7: 13.014 | G7: 0.254
A8: overall | B8: 7 | C8: José Ramírez | D8: 3B | E8: 5 | F8: 12.761 | G8: 0.116
A9: overall | B9: 8 | C9: Vladimir Guerrero Jr. | D9: 1B | E9: 5 | F9: 12.645 | G9: 0.175
A10: overall | B10: 9 | C10: Fernando Tatis Jr. | D10: OF | E10: 5 | F10: 12.469 | G10: 0.524
A11: overall | B11: 10 | C11: Kyle Tucker | D11: OF | E11: 5 | F11: 11.945 | G11: 0.077
A12: overall | B12: 11 | C12: Corbin Carroll | D12: OF | E12: 5 | F12: 11.868 | G12: 0.151
A13: overall | B13: 12 | C13: Julio Rodríguez | D13: OF | E13: 5 | F13: 11.717 | G13: 0.081
... A568: overall | B568: 567 | C568: Jac Caglianone | D568: OF | E568: 24 | F568: 1.424 | G568: 0.002
A569: overall | B569: 568 | E569: 24 | F569: 1.421 | G569: 0.004
A570: overall | B570: 569 | C570: Spencer Steer | D570: 1B | E570: 24 | F570: 1.417 | G570: 0.001
A571: overall | B571: 570 | C571: Will Klein | D571: RP | E571: 24 | F571: 1.416 | G571: 0.013
A572: overall | B572: 571 | C572: Austin Hays | D572: OF | E572: 24 | F572: 1.404 | G572: 0.006
A573: overall | B573: 572 | C573: Hunter Bigge | D573: RP | E573: 24 | F573: 1.398 | G573: 0.006
A574: overall | B574: 573 | C574: Sam Hentges | D574: RP | E574: 24 | F574: 1.392 | G574: 0.005
A575: overall | B575: 574 | C575: DL Hall | D575: RP | E575: 24 | F575: 1.387 | G575: 0.009
A576: overall | B576: 575 | C576: Matt Vierling | D576: OF | E576: 24 | F576: 1.377 | G576: 0.03
A577: overall | B577: 576 | C577: Moisés Ballesteros | D577: C | E577: 24 | F577: 1.348 | G577: 0.014
A578: overall | B578: 577 | C578: Kyle Harrison | D578: SP | E578: 24 | F578: 1.334 | G578: 0.002
A579: overall | B579: 578 | C579: Kevin Kelly | D579: RP | E579: 24 | F579: 1.332 | G579: 0.005
A580: overall | B580: 579 | C580: Hayden Harris | D580: RP | E580: 24 | F580: 1.327 | G580: 0.001
A581: overall | B581: 580 | C581: Nolan Gorman | D581: 2B | E581: 24 | F581: 1.326 | G581: 0.009
... A673: overall | B673: 672 | C673: Sam Moll | D673: RP | E673: 27 | F673: 0.572 | G673: 0.005
A674: overall | B674: 673 | E674: 27 | F674: 0.567 | G674: 0.005
A675: overall | B675: 674 | C675: Stephen Kolek | D675: P | E675: 27 | F675: 0.562 | G675: 0.006
A676: overall | B676: 675 | C676: Masataka Yoshida | D676: DH | E676: 27 | F676: 0.556 | G676: 0.011
A677: overall | B677: 676 | C677: Richard Lovelady | D677: RP | E677: 27 | F677: 0.546 | G677: 0.008
A678: overall | B678: 677 | C678: Edgardo Henriquez | D678: RP | E678: 27 | F678: 0.538 | G678: 0.02
A679: overall | B679: 678 | C679: Dylan Dodd | D679: RP | E679: 28 | F679: 0.518 | G679: 0.01
A680: overall | B680: 679 | C680: Spencer Arrighetti | D680: SP | E680: 28 | F680: 0.508 | G680: 0.002
A681: overall | B681: 680 | C681: Jonny DeLuca | D681: OF | E681: 28 | F681: 0.506 | G681: 0.009
A682: overall | B682: 681 | C682: Bradgley Rodriguez | D682: RP | E682: 28 | F682: 0.497 | G682: 0.006
A683: overall | B683: 682 | C683: Ryan Brasier | D683: RP | E683: 28 | F683: 0.491 | G683: 0.004
A684: overall | B684: 683 | C684: Colin Selby | D684: RP | E684: 28 | F684: 0.487 | G684: 0.009
A685: overall | B685: 684 | E685: 28 | F685: 0.478 | G685: 0.005
...

Sheet scarcity_sheet
A1: group | B1: sample_rank | C1: player_name | D1: final_score | E1: gap_from_prev
A2: C | B2: 1 | C2: Cal Raleigh | D2: 7.477
A3: C | B3: 12 | C3: Gabriel Moreno | D3: 3.36 | E3: 0.247
A4: C | B4: 24 | C4: Freddy Fermin | D4: 0.362 | E4: 0.322
A5: C | B5: 36 | C5: Dillon Dingler | D5: -0.974 | E5: 0.102
A6: 1B | B6: 1 | C6: Vladimir Guerrero Jr. | D6: 12.645
A7: 1B | B7: 12 | C7: Vinnie Pasquantino | D7: 5.962 | E7: 0.263
A8: 1B | B8: 24 | C8: Christian Walker | D8: 2.715 | E8: 0.035
A9: 1B | B9: 36 | C9: Tyler Locklear | D9: -0.643 | E9: 0.015
A10: 2B | B10: 1 | C10: Ketel Marte | D10: 9.66
A11: 2B | B11: 12 | C11: Andrés Giménez | D11: 4.391 | E11: 0.295
A12: 2B | B12: 24 | C12: Nolan Gorman | D12: 1.326 | E12: 0.683
A13: 3B | B13: 1 | C13: José Ramírez | D13: 12.761
A14: 3B | B14: 12 | C14: Colt Keith | D14: 4.253 | E14: 0.074
A15: 3B | B15: 24 | C15: Luis Rengifo | D15: 1.783 | E15: 0.212
A16: 3B | B16: 36 | C16: Ben Williamson | D16: 0.353 | E16: 0.292
A17: SS | B17: 1 | C17: Bobby Witt Jr. | D17: 15.005
A18: SS | B18: 12 | C18: Bo Bichette | D18: 6.258 | E18: 0.718
A19: SS | B19: 24 | C19: Joey Ortiz | D19: 3.598 | E19: 0.361
A20: SS | B20: 36 | C20: Javier Báez | D20: -1.087 | E20: 0.424
A21: OF | B21: 1 | C21: Aaron Judge | D21: 17.111
A22: OF | B22: 12 | C22: Brent Rooker | D22: 8.727 | E22: 0.145
A23: OF | B23: 24 | C23: Steven Kwan | D23: 6.297 | E23: 0.008
A24: OF | B24: 36 | C24: Tyler Soderstrom | D24: 5.056 | E24: 0.071
A25: OF | B25: 48 | C25: Wilyer Abreu | D25: 4.191 | E25: 0.012
A26: OF | B26: 60 | C26: Jesús Sánchez | D26: 3.241 | E26: 0.034
A27: DH | B27: 1 | C27: Shohei Ohtani | D27: 17.972
A28: BAT | B28: 1 | C28: Luis García Jr. | D28: 4.338
A29: BAT | B29: 12 | C29: Darell Hernaiz | D29: -0.198 | E29: 0.053
A30: BAT | B30: 24 | C30: Jeremiah Jackson | D30: -0.927 | E30: 0.114
A31: BAT | B31: 36 | C31: Adrian Del Castillo | D31: -1.22 | E31: 0.039
A32: BAT | B32: 48 | C32: Kyle Higashioka | D32: -1.444 | E32: 0.031
A33: BAT | B33: 60 | C33: Myles Straw | D33: -1.627 | E33: 0.024
A34: SP | B34: 1 | C34: Tarik Skubal | D34: 13.014
A35: SP | B35: 12 | C35: Max Fried | D35: 7.776 | E35: 0.053
A36: SP | B36: 24 | C36: Luis Castillo | D36: 6.05 | E36: 0.043
A37: SP | B37: 36 | C37: Spencer Strider | D37: 5.232 | E37: 0.01
A38: SP | B38: 48 | C38: Shota Imanaga | D38: 4.728 | E38: 0.036
A39: SP | B39: 60 | C39: Spencer Schwellenbach | D39: 4.21 | E39: 0.001
A40: RP | B40: 1 | C40: Mason Miller | D40: 8.038
...

Sheet category_contribution
A1: overall_rank | B1: player_name | C1: team | D1: inferred_role | E1: best_category | F1: best_category_score | G1: note | H1: R_z | I1: RBI_z | J1: HR_z | K1: SB_z | L1: AVG_z | M1: OBP_z | N1: QS_z | O1: K_z | P1: Saves_plus_Holds_z | Q1: ERA_z | R1: WHIP_z
A2: 1 | B2: Shohei Ohtani | C2: LAD | D2: DH | E2: HR | F2: 3.937 | G2: speed specialist | H2: 3.126 | I2: 2.702 | J2: 3.937 | K2: 2.358 | L2: 2.146 | M2: 3.251
A3: 2 | B3: Aaron Judge | C3: NYY | D3: OF | E3: OBP | F3: 4.719 | G3: power boost | H3: 2.602 | I3: 2.806 | J3: 3.967 | K3: 0.266 | L3: 2.475 | M3: 4.719
A4: 3 | B4: Juan Soto | C4: NYM | D4: OF | E4: OBP | F4: 4.362 | G4: speed specialist | H4: 2.592 | I4: 2.208 | J4: 2.951 | K4: 1.794 | L4: 1.689 | M4: 4.362
A5: 4 | B5: Bobby Witt Jr. | C5: KCR | D5: SS | E5: SB | F5: 3.737 | G5: speed specialist | H5: 2.331 | I5: 2.057 | J5: 2.035 | K5: 3.737 | L5: 2.763 | M5: 1.665
A6: 5 | B6: Ronald Acuña Jr. | C6: ATL | D6: OF | E6: OBP | F6: 3.282 | G6: speed specialist | H6: 2.533 | I6: 1.616 | J6: 2.088 | K6: 2.526 | L6: 2.185 | M6: 3.282
A7: 6 | B7: Tarik Skubal | C7: DET | D7: SP | E7: K | F7: 3.646 | G7: strikeout arm | N7: 3.329 | O7: 3.646 | P7: -0.74 | Q7: 3.117 | R7: 3.518
A8: 7 | B8: José Ramírez | C8: CLE | D8: 3B | E8: SB | F8: 3.531 | G8: speed specialist | H8: 1.851 | I8: 1.867 | J8: 1.817 | K8: 3.531 | L8: 1.74 | M8: 1.577
A9: 8 | B9: Vladimir Guerrero Jr. | C9: TOR | D9: 1B | E9: OBP | F9: 3.1 | G9: power boost | H9: 2.09 | I9: 2.273 | J9: 2.226 | K9: -0.219 | L9: 3.006 | M9: 3.1
A10: 9 | B10: Fernando Tatis Jr. | C10: SDP | D10: OF | E10: SB | F10: 2.424 | G10: speed specialist | H10: 2.225 | I10: 1.665 | J10: 2.073 | K10: 2.424 | L10: 1.688 | M10: 2.049
A11: 10 | B11: Kyle Tucker | C11: LAD | D11: OF | E11: OBP | F11: 2.613 | G11: speed specialist | H11: 2.029 | I11: 1.743 | J11: 1.966 | K11: 1.817 | L11: 1.494 | M11: 2.613
A12: 11 | B12: Corbin Carroll | C12: ARI | D12: OF | E12: SB | F12: 3.579 | G12: speed specialist | H12: 2.161 | I12: 1.508 | J12: 1.688 | K12: 3.579 | L12: 0.962 | M12: 1.553
A13: 12 | B13: Julio Rodríguez | C13: SEA | D13: OF | E13: SB | F13: 2.613 | G13: speed specialist | H13: 1.964 | I13: 1.993 | J13: 2.086 | K13: 2.613 | L13: 1.735 | M13: 0.998
A14: 13 | B14: Paul Skenes | C14: PIT | D14: SP | E14: K | F14: 3.422 | G14: strikeout arm | N14: 3.143 | O14: 3.422 | P14: -0.74 | Q14: 2.89 | R14: 2.77
A15: 14 | B15: Yordan Alvarez | C15: HOU | D15: OF | E15: OBP | F15: 3.355 | G15: power boost | H15: 1.555 | I15: 1.915 | J15: 2.208 | K15: -0.414 | L15: 2.78 | M15: 3.355
A16: 15 | B16: Gunnar Henderson | C16: BAL | D16: SS | E16: SB | F16: 2.256 | G16: speed specialist | H16: 2.204 | I16: 1.672 | J16: 1.764 | K16: 2.256 | L16: 1.606 | M16: 1.747
A17: 16 | B17: Elly De La Cruz | C17: CIN | D17: SS | E17: SB | F17: 4.536 | G17: speed specialist | H17: 1.857 | I17: 1.456 | J17: 1.305 | K17: 4.536 | L17: 0.96 | M17: 0.993
A18: 17 | B18: Garrett Crochet | C18: BOS | D18: SP | E18: K | F18: 3.584 | G18: strikeout arm | N18: 3.05 | O18: 3.584 | P18: -0.74 | Q18: 2.515 | R18: 2.602
A19: 18 | B19: Bryce Harper | C19: PHI | D19: 1B | E19: OBP | F19: 2.455 | G19: power boost | H19: 1.624 | I19: 1.797 | J19: 1.734 | K19: 0.399 | L19: 1.699 | M19: 2.455
A20: 19 | B20: Trea Turner | C20: PHI | D20: SS | E20: SB | F20: 2.751 | G20: speed specialist | H20: 1.788 | I20: 1.161 | J20: 0.746 | K20: 2.751 | L20: 2.224 | M20: 0.969
A21: 20 | B21: Ketel Marte | C21: ARI | D21: 2B | E21: OBP | F21: 2.268 | G21: power boost | H21: 1.839 | I21: 1.723 | J21: 1.862 | K21: -0.154 | L21: 1.948 | M21: 2.268
A22: 21 | B22: Francisco Lindor | C22: NYM | D22: SS | E22: SB | F22: 2.195 | G22: speed specialist | H22: 1.96 | I22: 1.41 | J22: 1.629 | K22: 2.195 | L22: 0.9 | M22: 1.038
A23: 22 | B23: Freddie Freeman | C23: LAD | D23: 1B | E23: OBP | F23: 2.125 | G23: power boost | H23: 1.718 | I23: 1.86 | J23: 1.329 | K23: 0.126 | L23: 1.918 | M23: 2.125
A24: 23 | B24: Kyle Schwarber | C24: PHI | D24: OF | E24: HR | F24: 3.356 | G24: power boost | H24: 2.149 | I24: 2.376 | J24: 3.356 | K24: -0.064 | L24: -0.621 | M24: 1.815
A25: 24 | B25: Chris Sale | C25: ATL | D25: SP | E25: K | F25: 2.797 | G25: strikeout arm | N25: 2.483 | O25: 2.797 | P25: -0.74 | Q25: 2.023 | R25: 2.271
A26: 25 | B26: Nick Kurtz | C26: ATH | D26: 1B | E26: HR | F26: 2.924 | G26: power boost | H26: 1.973 | I26: 1.995 | J26: 2.924 | K26: -0.414 | L26: 0.877 | M26: 1.451
A27: 26 | B27: Jackson Chourio | C27: MIL | D27: OF | E27: SB | F27: 2.289 | G27: speed specialist | H27: 1.658 | I27: 1.551 | J27: 1.364 | K27: 2.289 | L27: 1.518 | M27: 0.314
A28: 27 | B28: Junior Caminero | C28: TBR | D28: 3B | E28: HR | F28: 2.873 | G28: power boost | H28: 1.572 | I28: 2.445 | J28: 2.873 | K28: -0.152 | L28: 1.533 | M28: 0.472
A29: 28 | B29: James Wood | C29: WSN | D29: OF | E29: OBP | F29: 1.689 | G29: speed specialist | H29: 1.652 | I29: 1.461 | J29: 1.531 | K29: 1.354 | L29: 0.931 | M29: 1.689
A30: 29 | B30: Bryan Woo | C30: SEA | D30: SP | E30: QS | F30: 2.733 | G30: strikeout arm | N30: 2.733 | O30: 2.635 | P30: -0.74 | Q30: 1.427 | R30: 2.534
A31: 30 | B31: Zach Neto | C31: LAA | D31: SS | E31: SB | F31: 2.791 | G31: speed specialist | H31: 1.695 | I31: 1.304 | J31: 1.726 | K31: 2.791 | L31: 0.519 | M31: 0.404
A32: 31 | B32: Cristopher Sánchez | C32: PHI | D32: SP | E32: QS | F32: 3.014 | G32: strikeout arm | N32: 3.014 | O32: 2.557 | P32: -0.74 | Q32: 2.115 | R32: 1.639
A33: 32 | B33: Brent Rooker | C33: ATH | D33: OF | E33: HR | F33: 2.395 | G33: power boost | H33: 1.729 | I33: 2.119 | J33: 2.395 | K33: -0.075 | L33: 1.128 | M33: 1.21
A34: 33 | B34: Wyatt Langford | C34: TEX | D34: OF | E34: SB | F34: 1.946 | G34: speed specialist | H34: 1.616 | I34: 1.278 | J34: 1.441 | K34: 1.946 | L34: 0.597 | M34: 1.522
A35: 34 | B35: Logan Webb | C35: SFG | D35: SP | E35: QS | F35: 3.027 | G35: strikeout arm | N35: 3.027 | O35: 2.553 | P35: -0.731 | Q35: 1.911 | R35: 1.323
A36: 35 | B36: Maikel Garcia | C36: KCR | D36: 3B | E36: SB | F36: 2.65 | G36: speed specialist | H36: 1.596 | I36: 0.957 | J36: 0.187 | K36: 2.65 | L36: 1.628 | M36: 0.952
A37: 36 | B37: Yandy Díaz | C37: TBR | D37: 1B | E37: AVG | F37: 2.474 | G37: power boost | H37: 1.424 | I37: 1.333 | J37: 1.073 | K37: -0.578 | L37: 2.474 | M37: 2.112
A38: 37 | B38: Logan Gilbert | C38: SEA | D38: SP | E38: WHIP | F38: 2.484 | G38: strikeout arm | N38: 2.301 | O38: 2.445 | P38: -0.74 | Q38: 1.531 | R38: 2.484
A39: 38 | B39: George Springer | C39: TOR | D39: OF | E39: R | F39: 1.638 | G39: power boost | H39: 1.638 | I39: 1.295 | J39: 1.623 | K39: 0.898 | L39: 1.009 | M39: 1.338
A40: 39 | B40: Pete Alonso | C40: BAL | D40: 1B | E40: HR | F40: 2.848 | G40: power boost | H40: 1.767 | I40: 2.415 | J40: 2.848 | K40: -0.583 | L40: 0.597 | M40: 1.049
...

Sheet sleepers_fades
A1: market_call | B1: position_group | C1: position_rank | D1: overall_rank | E1: player_name | F1: team | G1: inferred_role | H1: adp | I1: adp_gap | J1: tier | K1: dropoff_to_next | L1: note
A2: Sleeper | B2: C | C2: 1 | D2: 352 | E2: Carter Jensen | F2: KCR | G2: C | H2: 999 | I2: 647 | J2: 17 | K2: 0.013 | L2: value target
A3: Sleeper | B3: C | C3: 2 | D3: 638 | E3: Joey Bart | F3: PIT | G3: C | H3: 999 | I3: 361 | J3: 26 | K3: 0.006 | L3: value target
A4: Sleeper | B4: C | C4: 3 | D4: 701 | E4: Danny Jansen | F4: TEX | G4: C | H4: 999 | I4: 298 | J4: 28 | K4: 0.002 | L4: value target
A5: Sleeper | B5: C | C5: 4 | D5: 789 | E5: Luis Campusano | F5: SDP | G5: C | H5: 999 | I5: 210 | J5: 31 | K5: 0.007 | L5: value target
A6: Sleeper | B6: C | C6: 5 | D6: 84 | E6: Iván Herrera | F6: STL | G6: C | H6: 176.37 | I6: 92.37 | J6: 8 | K6: 0.025 | L6: ratio stabilizer
A7: Sleeper | B7: 1B | C7: 1 | D7: 387 | E7: Pavin Smith | F7: ARI | G7: 1B | H7: 999 | I7: 612 | J7: 18 | K7: 0.02 | L7: value target
A8: Sleeper | B8: 1B | C8: 2 | D8: 223 | E8: Spencer Horwitz | F8: PIT | G8: 1B | H8: 739.93 | I8: 516.93 | J8: 12 | K8: 0.002 | L8: ratio stabilizer
A9: Sleeper | B9: 1B | C9: 3 | D9: 72 | E9: Nolan Schanuel | F9: LAA | G9: 1B | H9: 586.56 | I9: 514.56 | J9: 7 | K9: 0.151 | L9: ratio stabilizer
A10: Sleeper | B10: 1B | C10: 4 | D10: 157 | E10: Josh Bell | F10: MIN | G10: 1B | H10: 640.3 | I10: 483.3 | J10: 10 | K10: 0.001 | L10: ratio stabilizer
A11: Sleeper | B11: 1B | C11: 5 | D11: 633 | E11: Jake Bauers | F11: MIL | G11: 1B | H11: 999 | I11: 366 | J11: 26 | K11: 0 | L11: value target
A12: Sleeper | B12: 2B | C12: 1 | D12: 372 | E12: Nick Gonzales | F12: PIT | G12: 2B | H12: 999 | I12: 627 | J12: 17 | K12: 0.007 | L12: ratio stabilizer
A13: Sleeper | B13: 2B | C13: 2 | D13: 188 | E13: Jake Cronenworth | F13: SDP | G13: 2B | H13: 740.05 | I13: 552.05 | J13: 11 | K13: 0.029 | L13: ratio stabilizer
... A45: Sleeper | B45: BAT | C45: 1 | D45: 556 | E45: Romy Gonzalez | F45: BOS | G45: BAT | H45: 999 | I45: 443 | J45: 23 | K45: 0.002 | L45: ratio stabilizer
A46: Sleeper | B46: BAT | C46: 2 | D46: 630 | E46: Jesse Winker | G46: BAT | H46: 999 | I46: 369 | J46: 26 | K46: 0.015 | L46: ratio stabilizer
A47: Sleeper | B47: BAT | C47: 3 | D47: 723 | E47: Alan Roden | F47: MIN | G47: BAT | H47: 999 | I47: 276 | J47: 29 | K47: 0.007 | L47: value target
A48: Sleeper | B48: BAT | C48: 4 | D48: 735 | E48: Tommy Pham | G48: BAT | H48: 999 | I48: 264 | J48: 29 | K48: 0.003 | L48: value target
A49: Sleeper | B49: BAT | C49: 5 | D49: 736 | E49: José Fermín | F49: STL | G49: BAT | H49: 999 | I49: 263 | J49: 29 | K49: 0.011 | L49: value target
A50: Sleeper | B50: P | C50: 1 | D50: 238 | E50: Drew Anderson | F50: DET | G50: P | H50: 999 | I50: 761 | J50: 13 | K50: 0.002 | L50: pitching depth
A51: Sleeper | B51: P | C51: 2 | D51: 368 | E51: Tobias Myers | F51: NYM | G51: P | H51: 999 | I51: 631 | J51: 17 | K51: 0.018 | L51: pitching depth
A52: Sleeper | B52: P | C52: 3 | D52: 439 | E52: Kutter Crawford | F52: BOS | G52: P | H52: 999 | I52: 560 | J52: 20 | K52: 0.012 | L52: pitching depth
A53: Sleeper | B53: P | C53: 4 | D53: 489 | E53: Cooper Criswell | F53: SEA | G53: P | H53: 999 | I53: 510 | J53: 21 | K53: 0.023 | L53: pitching depth
A54: Sleeper | B54: P | C54: 5 | D54: 491 | E54: Cody Bradford | F54: TEX | G54: P | H54: 999 | I54: 508 | J54: 21 | K54: 0.007 | L54: pitching depth
A55: Fade | B55: C | C55: 1 | D55: 866 | E55: Dillon Dingler | F55: DET | G55: C | H55: 256.49 | I55: -609.51 | J55: 34 | K55: 0.006 | L55: balanced bat
A56: Fade | B56: C | C56: 2 | D56: 733 | E56: Samuel Basallo | F56: BAL | G56: C | H56: 163.87 | I56: -569.13 | J56: 29 | K56: 0.007 | L56: balanced bat
A57: Fade | B57: C | C57: 3 | D57: 813 | E57: Logan O'Hoppe | F57: LAA | G57: C | H57: 245.11 | I57: -567.89 | J57: 32 | K57: 0.011 | L57: balanced bat
A58: Fade | B58: C | C58: 4 | D58: 790 | E58: Austin Wells | F58: NYY | G58: C | H58: 248.33 | I58: -541.67 | J58: 31 | K58: 0 | L58: balanced bat
A59: Fade | B59: C | C59: 5 | D59: 707 | E59: Francisco Alvarez | F59: NYM | G59: C | H59: 165.39 | I59: -541.61 | J59: 28 | K59: 0.004 | L59: balanced bat
A60: Fade | B60: 1B | C60: 1 | D60: 569 | E60: Spencer Steer | F60: CIN | G60: 1B | H60: 335.43 | I60: -233.57 | J60: 24 | K60: 0.001 | L60: value target
... A104: Fade | B104: P | C104: 5 | D104: 1052 | E104: Antonio Senzatela | F104: COL | G104: P | H104: 999 | I104: -53 | J104: 40 | K104: 0.089 | L104: pitching depth

Sheet draft_day_queue
A1: queue_rank | B1: overall_rank | C1: player_name | D1: team | E1: inferred_role | F1: adp | G1: adp_gap | H1: queue_score | I1: final_score | J1: dropoff_to_next | K1: tier | L1: note | M1: taken_status | N1: available_flag
A2: 1 | B2: 1 | C2: Shohei Ohtani | D2: LAD | E2: DH | F2: 1.26 | G2: 0.26 | H2: 18.322 | I2: 17.972 | J2: 0.861 | K2: 1 | L2: speed specialist | M2: =XLOOKUP(C2,overall_board!$B$2:$B$2000,overall_board!$L$2:$L$2000,"") | N2: =IF(L2="","available","taken")
A3: 2 | B3: 2 | C3: Aaron Judge | D3: NYY | E3: OF | F3: 1.86 | G3: -0.14 | H3: 17.461 | I3: 17.111 | J3: 1.186 | K3: 2 | L3: power boost | M3: =XLOOKUP(C3,overall_board!$B$2:$B$2000,overall_board!$L$2:$L$2000,"") | N3: =IF(L3="","available","taken")
A4: 3 | B4: 3 | C4: Juan Soto | D4: NYM | E4: OF | F4: 4.68 | G4: 1.68 | H4: 16.275 | I4: 15.925 | J4: 0.921 | K4: 3 | L4: speed specialist | M4: =XLOOKUP(C4,overall_board!$B$2:$B$2000,overall_board!$L$2:$L$2000,"") | N4: =IF(L4="","available","taken")
A5: 4 | B5: 4 | C5: Bobby Witt Jr. | D5: KCR | E5: SS | F5: 3.07 | G5: -0.93 | H5: 15.355 | I5: 15.005 | J5: 0.447 | K5: 4 | L5: speed specialist | M5: =XLOOKUP(C5,overall_board!$B$2:$B$2000,overall_board!$L$2:$L$2000,"") | N5: =IF(L5="","available","taken")
A6: 5 | B6: 5 | C6: Ronald Acuña Jr. | D6: ATL | E6: OF | F6: 5.32 | G6: 0.32 | H6: 14.908 | I6: 14.558 | J6: 1.543 | K6: 4 | L6: speed specialist | M6: =XLOOKUP(C6,overall_board!$B$2:$B$2000,overall_board!$L$2:$L$2000,"") | N6: =IF(L6="","available","taken")
A7: 6 | B7: 7 | C7: José Ramírez | D7: CLE | E7: 3B | F7: 6.23 | G7: -0.77 | H7: 13.111 | I7: 12.761 | J7: 0.116 | K7: 5 | L7: speed specialist | M7: =XLOOKUP(C7,overall_board!$B$2:$B$2000,overall_board!$L$2:$L$2000,"") | N7: =IF(L7="","available","taken")
A8: 7 | B8: 8 | C8: Vladimir Guerrero Jr. | D8: TOR | E8: 1B | F8: 18.13 | G8: 10.13 | H8: 12.995 | I8: 12.645 | J8: 0.175 | K8: 5 | L8: power boost | M8: =XLOOKUP(C8,overall_board!$B$2:$B$2000,overall_board!$L$2:$L$2000,"") | N8: =IF(L8="","available","taken")
A9: 8 | B9: 9 | C9: Fernando Tatis Jr. | D9: SDP | E9: OF | F9: 14.06 | G9: 5.06 | H9: 12.819 | I9: 12.469 | J9: 0.524 | K9: 5 | L9: speed specialist | M9: =XLOOKUP(C9,overall_board!$B$2:$B$2000,overall_board!$L$2:$L$2000,"") | N9: =IF(L9="","available","taken")
A10: 9 | B10: 6 | C10: Tarik Skubal | D10: DET | E10: SP | F10: 6.91 | G10: 0.91 | H10: 12.764 | I10: 13.014 | J10: 0.254 | K10: 5 | L10: strikeout arm | M10: =XLOOKUP(C10,overall_board!$B$2:$B$2000,overall_board!$L$2:$L$2000,"") | N10: =IF(L10="","available","taken")
A11: 10 | B11: 10 | C11: Kyle Tucker | D11: LAD | E11: OF | F11: 13.17 | G11: 3.17 | H11: 12.295 | I11: 11.945 | J11: 0.077 | K11: 5 | L11: speed specialist | M11: =XLOOKUP(C11,overall_board!$B$2:$B$2000,overall_board!$L$2:$L$2000,"") | N11: =IF(L11="","available","taken")
A12: 11 | B12: 11 | C12: Corbin Carroll | D12: ARI | E12: OF | F12: 14.14 | G12: 3.14 | H12: 12.218 | I12: 11.868 | J12: 0.151 | K12: 5 | L12: speed specialist | M12: =XLOOKUP(C12,overall_board!$B$2:$B$2000,overall_board!$L$2:$L$2000,"") | N12: =IF(L12="","available","taken")
A13: 12 | B13: 12 | C13: Julio Rodríguez | D13: SEA | E13: OF | F13: 9.54 | G13: -2.46 | H13: 12.067 | I13: 11.717 | J13: 0.081 | K13: 5 | L13: speed specialist | M13: =XLOOKUP(C13,overall_board!$B$2:$B$2000,overall_board!$L$2:$L$2000,"") | N13: =IF(L13="","available","taken")
... A508: 507 | B508: 479 | C508: Hogan Harris | D508: ATH | E508: RP | F508: 631.42 | G508: 152.42 | H508: 1.845 | I508: 2.195 | J508: 0.015 | K508: 21 | L508: RP saves+holds | M508: =XLOOKUP(C508,overall_board!$B$2:$B$2000,overall_board!$L$2:$L$2000,"") | N508: =IF(L508="","available","taken")
A509: 508 | B509: 492 | C509: Luis Garcia | E509: RP | F509: 999 | G509: 507 | H509: 1.841 | I509: 2.091 | J509: 0.007 | K509: 21 | L509: pitching depth | M509: =XLOOKUP(C509,overall_board!$B$2:$B$2000,overall_board!$L$2:$L$2000,"") | N509: =IF(L509="","available","taken")
A510: 509 | B510: 480 | C510: Kenley Jansen | D510: DET | E510: RP | F510: 133.66 | G510: -346.34 | H510: 1.83 | I510: 2.18 | J510: 0.002 | K510: 21 | L510: RP saves+holds | M510: =XLOOKUP(C510,overall_board!$B$2:$B$2000,overall_board!$L$2:$L$2000,"") | N510: =IF(L510="","available","taken")
A511: 510 | B511: 495 | C511: Matt Gage | D511: SFG | E511: RP | F511: 999 | G511: 504 | H511: 1.824 | I511: 2.074 | J511: 0.013 | K511: 21 | L511: pitching depth | M511: =XLOOKUP(C511,overall_board!$B$2:$B$2000,overall_board!$L$2:$L$2000,"") | N511: =IF(L511="","available","taken")
A512: 511 | B512: 561 | C512: Marcelo Mayer | D512: BOS | E512: 3B | F512: 588.92 | G512: 27.92 | H512: 1.815 | I512: 1.465 | J512: 0.021 | K512: 24 | L512: value target | M512: =XLOOKUP(C512,overall_board!$B$2:$B$2000,overall_board!$L$2:$L$2000,"") | N512: =IF(L512="","available","taken")
A513: 512 | B513: 496 | C513: Jordan Hicks | D513: CHW | E513: RP | F513: 999 | G513: 503 | H513: 1.811 | I513: 2.061 | J513: 0.012 | K513: 21 | L513: pitching depth | M513: =XLOOKUP(C513,overall_board!$B$2:$B$2000,overall_board!$L$2:$L$2000,"") | N513: =IF(L513="","available","taken")
A514: 513 | B514: 497 | C514: Grant Anderson | D514: MIL | E514: RP | F514: 999 | G514: 502 | H514: 1.799 | I514: 2.049 | J514: 0.005 | K514: 21 | L514: pitching depth | M514: =XLOOKUP(C514,overall_board!$B$2:$B$2000,overall_board!$L$2:$L$2000,"") | N514: =IF(L514="","available","taken")
A515: 514 | B515: 488 | C515: Tim Hill | D515: NYY | E515: RP | F515: 999 | G515: 511 | H515: 1.795 | I515: 2.145 | J515: 0 | K515: 21 | L515: RP saves+holds | M515: =XLOOKUP(C515,overall_board!$B$2:$B$2000,overall_board!$L$2:$L$2000,"") | N515: =IF(L515="","available","taken")
A516: 515 | B516: 498 | C516: Cole Sulser | D516: TBR | E516: RP | F516: 999 | G516: 501 | H516: 1.794 | I516: 2.044 | J516: 0.004 | K516: 22 | L516: pitching depth | M516: =XLOOKUP(C516,overall_board!$B$2:$B$2000,overall_board!$L$2:$L$2000,"") | N516: =IF(L516="","available","taken")
A517: 516 | B517: 499 | C517: Anthony Kay | D517: CHW | E517: SP | F517: 717.81 | G517: 218.81 | H517: 1.79 | I517: 2.04 | J517: 0.011 | K517: 22 | L517: SP value | M517: =XLOOKUP(C517,overall_board!$B$2:$B$2000,overall_board!$L$2:$L$2000,"") | N517: =IF(L517="","available","taken")
A518: 517 | B518: 564 | C518: Wenceel Pérez | D518: DET | E518: OF | F518: 748.32 | G518: 184.32 | H518: 1.785 | I518: 1.435 | J518: 0.002 | K518: 24 | L518: value target | M518: =XLOOKUP(C518,overall_board!$B$2:$B$2000,overall_board!$L$2:$L$2000,"") | N518: =IF(L518="","available","taken")
A519: 518 | B519: 500 | C519: Josh Sborz | D519: TEX | E519: RP | F519: 999 | G519: 499 | H519: 1.779 | I519: 2.029 | J519: 0.004 | K519: 22 | L519: pitching depth | M519: =XLOOKUP(C519,overall_board!$B$2:$B$2000,overall_board!$L$2:$L$2000,"") | N519: =IF(L519="","available","taken")
A520: 519 | B520: 501 | C520: Jalen Beeks | D520: TEX | E520: RP | F520: 999 | G520: 498 | H520: 1.774 | I520: 2.024 | J520: 0.001 | K520: 22 | L520: pitching depth | M520: =XLOOKUP(C520,overall_board!$B$2:$B$2000,overall_board!$L$2:$L$2000,"") | N520: =IF(L520="","available","taken")
A521: 520 | B521: 567 | C521: Jac Caglianone | D521: KCR | E521: OF | F521: 167.34 | G521: -399.66 | H521: 1.774 | I521: 1.424 | J521: 0.002 | K521: 24 | L521: balanced bat | M521: =XLOOKUP(C521,overall_board!$B$2:$B$2000,overall_board!$L$2:$L$2000,"") | N521: =IF(L521="","available","taken")
... A585: 584 | B585: 628 | C585: Brett Baty | D585: NYM | E585: 3B | F585: 293.78 | G585: -334.22 | H585: 1.281 | I585: 0.931 | J585: 0.001 | K585: 26 | L585: value target | M585: =XLOOKUP(C585,overall_board!$B$2:$B$2000,overall_board!$L$2:$L$2000,"") | N585: =IF(L585="","available","taken")
A586: 585 | B586: 630 | C586: Jesse Winker | E586: BAT | F586: 999 | G586: 369 | H586: 1.279 | I586: 0.929 | J586: 0.015 | K586: 26 | L586: ratio stabilizer | M586: =XLOOKUP(C586,overall_board!$B$2:$B$2000,overall_board!$L$2:$L$2000,"") | N586: =IF(L586="","available","taken")
A587: 586 | B587: 553 | C587: Zack Kelly | D587: BOS | E587: RP | F587: 999 | G587: 446 | H587: 1.278 | I587: 1.528 | J587: 0.006 | K587: 23 | L587: pitching depth | M587: =XLOOKUP(C587,overall_board!$B$2:$B$2000,overall_board!$L$2:$L$2000,"") | N587: =IF(L587="","available","taken")
A588: 587 | B588: 554 | C588: Rico Garcia | D588: BAL | E588: RP | F588: 999 | G588: 445 | H588: 1.272 | I588: 1.522 | J588: 0.015 | K588: 23 | L588: pitching depth | M588: =XLOOKUP(C588,overall_board!$B$2:$B$2000,overall_board!$L$2:$L$2000,"") | N588: =IF(L588="","available","taken")
A589: 588 | B589: 633 | C589: Jake Bauers | D589: MIL | E589: 1B | F589: 999 | G589: 366 | H589: 1.258 | I589: 0.908 | J589: 0 | K589: 26 | L589: value target | M589: =XLOOKUP(C589,overall_board!$B$2:$B$2000,overall_board!$L$2:$L$2000,"") | N589: =IF(L589="","available","taken")
A590: 589 | B590: 634 | C590: Jordan Lawlar | D590: ARI | E590: 3B | F590: 262.22 | G590: -371.78 | H590: 1.257 | I590: 0.907 | J590: 0.017 | K590: 26 | L590: balanced bat | M590: =XLOOKUP(C590,overall_board!$B$2:$B$2000,overall_board!$L$2:$L$2000,"") | N590: =IF(L590="","available","taken")
A591: 590 | B591: 555 | C591: Ryan Borucki | D591: SFG | E591: RP | F591: 999 | G591: 444 | H591: 1.256 | I591: 1.506 | J591: 0.003 | K591: 23 | L591: pitching depth | M591: =XLOOKUP(C591,overall_board!$B$2:$B$2000,overall_board!$L$2:$L$2000,"") | N591: =IF(L591="","available","taken")
A592: 591 | B592: 558 | C592: Brent Suter | D592: LAA | E592: RP | F592: 999 | G592: 441 | H592: 1.244 | I592: 1.494 | J592: 0.021 | K592: 24 | L592: pitching depth | M592: =XLOOKUP(C592,overall_board!$B$2:$B$2000,overall_board!$L$2:$L$2000,"") | N592: =IF(L592="","available","taken")
A593: 592 | B593: 635 | C593: Bryce Eldridge | D593: SFG | E593: 1B | F593: 999 | G593: 364 | H593: 1.241 | I593: 0.891 | J593: 0.007 | K593: 26 | L593: value target | M593: =XLOOKUP(C593,overall_board!$B$2:$B$2000,overall_board!$L$2:$L$2000,"") | N593: =IF(L593="","available","taken")
A594: 593 | B594: 559 | C594: Andrew Hoffmann | D594: ARI | E594: RP | F594: 999 | G594: 440 | H594: 1.224 | I594: 1.474 | J594: 0.003 | K594: 24 | L594: pitching depth | M594: =XLOOKUP(C594,overall_board!$B$2:$B$2000,overall_board!$L$2:$L$2000,"") | N594: =IF(L594="","available","taken")
A595: 594 | B595: 560 | C595: Chris Paddack | D595: MIA | E595: SP | F595: 748.29 | G595: 188.29 | H595: 1.22 | I595: 1.47 | J595: 0.005 | K595: 24 | L595: SP value | M595: =XLOOKUP(C595,overall_board!$B$2:$B$2000,overall_board!$L$2:$L$2000,"") | N595: =IF(L595="","available","taken")
A596: 595 | B596: 562 | C596: Luis Morales | D596: ATH | E596: SP | F596: 733.95 | G596: 171.95 | H596: 1.194 | I596: 1.444 | J596: 0.008 | K596: 24 | L596: SP value | M596: =XLOOKUP(C596,overall_board!$B$2:$B$2000,overall_board!$L$2:$L$2000,"") | N596: =IF(L596="","available","taken")
A597: 596 | B597: 638 | C597: Joey Bart | D597: PIT | E597: C | F597: 999 | G597: 361 | H597: 1.193 | I597: 0.843 | J597: 0.006 | K597: 26 | L597: value target | M597: =XLOOKUP(C597,overall_board!$B$2:$B$2000,overall_board!$L$2:$L$2000,"") | N597: =IF(L597="","available","taken")
...

Sheet player_pool
A1: player_name | B1: team | C1: inferred_role | D1: player_type | E1: final_score | F1: tier | G1: note | H1: adp | I1: adp_gap | J1: R_z | K1: RBI_z | L1: HR_z | M1: SB_z | N1: AVG_z | O1: OBP_z | P1: QS_z | Q1: K_z | R1: Saves_plus_Holds_z | S1: ERA_z | T1: WHIP_z | U1: PA | V1: R | W1: RBI | X1: HR | Y1: SB | Z1: AVG | AA1: OBP | AB1: IP | AC1: QS | AD1: K | AE1: Saves_plus_Holds | AF1: ERA | AG1: WHIP
A2: Shohei Ohtani | B2: LAD | C2: DH | D2: H | E2: 17.972423 | F2: 1 | G2: speed specialist | H2: 1.26 | I2: 0.25999999 | J2: 3.1263775 | K2: 2.7023642 | L2: 3.9370992 | M2: 2.3581679 | N2: 2.1455063 | O2: 3.2514228 | U2: 659.45 | V2: 120.75005 | W2: 107.97774 | X2: 45.53622 | Y2: 23.73994 | Z2: 0.2806479 | AA2: 0.3842773 | AD2: 159.19025
A3: Aaron Judge | B3: NYY | C3: OF | D3: H | E3: 17.111305 | F3: 2 | G3: power boost | H3: 1.86 | I3: -0.13999999 | J3: 2.6016093 | K3: 2.8060336 | L3: 3.9670853 | M3: 0.26586934 | N3: 2.474659 | O3: 4.7192457 | U3: 636.12895 | V3: 107.5767 | W3: 110.5562 | X3: 45.797035 | Y3: 8.5614295 | Z3: 0.2866472 | AA3: 0.41731895 | AD3: 157.96125
A4: Juan Soto | B4: NYM | C4: OF | D4: H | E4: 15.925148 | F4: 3 | G4: speed specialist | H4: 4.6799998 | I4: 1.6799998 | J4: 2.5920269 | K4: 2.2082499 | L4: 2.9507778 | M4: 1.7936653 | N4: 1.6887125 | O4: 4.3622436 | U4: 658.2899 | V4: 107.33615 | W4: 95.68818 | X4: 36.95734 | Y4: 19.644775 | Z4: 0.27232215 | AA4: 0.4092826 | AD4: 118.21825
A5: Bobby Witt Jr. | B5: KCR | C5: SS | D5: H | E5: 15.004635 | F5: 4 | G5: speed specialist | H5: 3.0699999 | I5: -0.93000007 | J5: 2.3307881 | K5: 2.0573964 | L5: 2.0347313 | M5: 3.7373795 | N5: 2.7627615 | O5: 1.664563 | U5: 650.4432 | V5: 100.77823 | W5: 91.936165 | X5: 28.9897 | Y5: 33.745385 | Z5: 0.2918983 | AA5: 0.34855605 | AD5: 110.5243
A6: Ronald Acuña Jr. | B6: ATL | C6: OF | D6: H | E6: 14.55788 | F6: 4 | G6: speed specialist | H6: 5.3200002 | I6: 0.32000017 | J6: 2.532638 | K6: 1.6164973 | L6: 2.0875782 | M6: 2.5258225 | N6: 2.1847212 | O6: 3.2818728 | U6: 645.5494 | V6: 105.8453 | W6: 80.970165 | X6: 29.449355 | Y6: 24.956185 | Z6: 0.28136265 | AA6: 0.38496275 | AD6: 135.15085
A7: Tarik Skubal | B7: DET | C7: SP | D7: P | E7: 13.014434 | F7: 5 | G7: strikeout arm | H7: 6.9099998 | I7: 0.90999985 | P7: 3.3290097 | Q7: 3.6464431 | R7: -0.73960027 | S7: 3.1166867 | T7: 3.5182548 | AB7: 195.16135 | AC7: 20.66009 | AD7: 237.37025 | AE7: 0 | AF7: 2.7316005 | AG7: 0.9905388
A8: José Ramírez | B8: CLE | C8: 3B | D8: H | E8: 12.760928 | F8: 5 | G8: speed specialist | H8: 6.23 | I8: -0.76999998 | J8: 1.8509641 | K8: 1.8672515 | L8: 1.817484 | M8: 3.5308495 | N8: 1.7400005 | O8: 1.5770089 | U8: 633.09035 | V8: 88.733115 | W8: 87.2069 | X8: 27.100115 | Y8: 32.24712 | Z8: 0.27325695 | AA8: 0.34658515 | AD8: 73.181975
A9: Vladimir Guerrero Jr. | B9: TOR | C9: 1B | D9: H | E9: 12.644672 | F9: 5 | G9: power boost | H9: 18.129999 | I9: 10.129999 | J9: 2.0896579 | K9: 2.2726501 | L9: 2.2256605 | M9: -0.21864523 | N9: 3.0063931 | O9: 3.0997546 | U9: 653.59685 | V9: 94.72509 | W9: 97.289935 | X9: 30.650375 | Y9: 5.0465345 | Z9: 0.29633885 | AA9: 0.38086315 | AD9: 88.763455
A10: Fernando Tatis Jr. | B10: SDP | C10: OF | D10: H | E10: 12.469356 | F10: 5 | G10: speed specialist | H10: 14.06 | I10: 5.0600004 | J10: 2.2249874 | K10: 1.6650736 | L10: 2.0734443 | M10: 2.4240624 | N10: 1.6877743 | O10: 2.0489121 | U10: 638.1283 | V10: 98.12229 | W10: 82.17835 | X10: 29.32642 | Y10: 24.21797 | Z10: 0.27230505 | AA10: 0.357208 | AD10: 125.63235
A11: Kyle Tucker | B11: LAD | C11: OF | D11: H | E11: 11.944858 | F11: 5 | G11: speed specialist | H11: 13.17 | I11: 3.1700001 | J11: 2.0287457 | K11: 1.7431488 | L11: 1.9655797 | M11: 1.8171012 | N11: 1.4936407 | O11: 2.6127206 | U11: 599.98565 | V11: 93.196 | W11: 84.12023 | X11: 28.38823 | Y11: 19.81479 | Z11: 0.268767 | AA11: 0.3699004 | AD11: 88.97533
A12: Corbin Carroll | B12: ARI | C12: OF | D12: H | E12: 11.868013 | F12: 5 | G12: speed specialist | H12: 14.14 | I12: 3.1400003 | J12: 2.1607796 | K12: 1.5077984 | L12: 1.687982 | M12: 3.5791569 | N12: 0.96248962 | O12: 1.5534911 | U12: 607.43075 | V12: 96.51047 | W12: 78.266615 | X12: 25.973725 | Y12: 32.597565 | Z12: 0.25908565 | AA12: 0.34605575 | AD12: 126.87735
A13: Julio Rodríguez | B13: SEA | C13: OF | D13: H | E13: 11.716526 | F13: 5 | G13: speed specialist | H13: 9.54 | I13: -2.46 | J13: 1.9636341 | K13: 1.9933235 | L13: 2.0856145 | M13: 2.613414 | N13: 1.7345826 | O13: 0.99769423 | U13: 645.3282 | V13: 91.56149 | W13: 90.34255 | X13: 29.432275 | Y13: 25.591615 | Z13: 0.2731582 | AA13: 0.3335444 | AD13: 141.77835
A14: Paul Skenes | B14: PIT | C14: SP | D14: P | E14: 11.635217 | F14: 5 | G14: strikeout arm | H14: 9.6599998 | I14: -3.3400002 | P14: 3.1429359 | Q14: 3.4216537 | R14: -0.73960027 | S14: 2.8898499 | T14: 2.7697373 | AB14: 189.1485 | AC14: 19.69852 | AD14: 227.23715 | AE14: 0 | AF14: 2.8331175 | AG14: 1.0586105
A15: Yordan Alvarez | B15: HOU | C15: OF | D15: H | E15: 11.596407 | F15: 5 | G15: power boost | H15: 33.209999 | I15: 19.209999 | J15: 1.55476 | K15: 1.9154145 | L15: 2.2077843 | M15: -0.41362544 | N15: 2.7801939 | O15: 3.355494 | U15: 553.2894 | V15: 81.29745 | W15: 88.404805 | X15: 30.49489 | Y15: 3.632057 | Z15: 0.2943117 | AA15: 0.38974385 | AD15: 93.314905
A16: Gunnar Henderson | B16: BAL | C16: SS | D16: H | E16: 11.538123 | F16: 5 | G16: speed specialist | H16: 12.44 | I16: -2.5600004 | J16: 2.2043456 | K16: 1.672212 | L16: 1.7644801 | M16: 2.2557461 | N16: 1.6059539 | O16: 1.7470195 | U16: 661.7923 | V16: 97.604115 | W16: 82.355895 | X16: 26.639095 | Y16: 22.996925 | Z16: 0.27081375 | AA16: 0.3504122 | AD16: 138.14305
A17: Elly De La Cruz | B17: CIN | C17: SS | D17: H | E17: 11.511933 | F17: 5 | G17: speed specialist | H17: 8.4700003 | I17: -7.5299997 | J17: 1.8571633 | K17: 1.4557213 | L17: 1.3050571 | M17: 4.5360136 | N17: 0.96012218 | O17: 0.992781 | U17: 631.94455 | V17: 88.888735 | W17: 76.97136 | X17: 22.6431 | Y17: 39.53905 | Z17: 0.2590425 | AA17: 0.3334338 | AD17: 167.06465
A18: Garrett Crochet | B18: BOS | C18: SP | D18: P | E18: 11.167325 | F18: 5 | G18: strikeout arm | H18: 12.1 | I18: -4.8999996 | P18: 3.0498264 | Q18: 3.5841503 | R18: -0.73960027 | S18: 2.514622 | T18: 2.6019271 | AB18: 189.96125 | AC18: 19.21736 | AD18: 234.5622 | AE18: 0 | AF18: 3.0010445 | AG18: 1.0738715
A19: Bryce Harper | B19: PHI | C19: 1B | D19: H | E19: 9.979616 | F19: 6 | G19: power boost | H19: 48.169998 | I19: 30.169998 | J19: 1.6242761 | K19: 1.7973765 | L19: 1.7335386 | M19: 0.3991484 | N19: 1.699425 | O19: 2.4551931 | U19: 603.694 | V19: 83.042525 | W19: 85.468975 | X19: 26.36997 | Y19: 9.528298 | Z19: 0.2725174 | AA19: 0.36635365 | AD19: 128.3443
